<?xml version="1.0" ?>
<robot name="wearable" xmlns:xacro="http://ros.org/wiki/xacro">
	<link name="world"/>
	<joint name="world_joint" type="fixed">
		<parent link="world"/>
		<child link="base_link"/>
		<origin rpy="0.0 0.0 0.0" xyz="0 0 0.5"/>
	</joint>
<link name="base_link">
		<visual>
		<origin rpy="0 0 0" xyz="0 0 0"/>
		<geometry>
		<mesh filename="meshes/base_link.stl"/>
		</geometry>
  <material name="black">
    <color rgba="0.4 0.4 0.4 1.0"/>
  </material>
		</visual>
		<collision>
		<origin rpy="0 0 0" xyz="0 0 0"/>
		<geometry>
		<mesh filename="meshes/base_link.stl"/>
		</geometry>
		</collision>
		<inertial>
		<origin rpy="0 0 0" xyz="0 0 0"/>
		<mass value="0.705"/>
		  <inertia  ixx="0.0006111993117592239" ixy="0" ixz="0" iyy="0.000993951145190498" iyz="0" izz="0.0006111993117592239" />
		</inertial>
	</link>
	<joint name="joint1" type="revolute">
		<parent link="base_link"/>
		<child link="link1"/>
		<origin rpy="0.0 0.0 0.0" xyz="0.20956 -0.1476 -0.075093"/>
		<axis xyz="1 0 0"/>
               <limit effort="10" lower="-3.05432619099" upper="3.05432619099" velocity="1"/>
	</joint>
<link name="link1">
		<visual>
		<origin rpy="0 0 0" xyz="0 0 0"/>
		<geometry>
		<mesh filename="meshes/link1.stl"/>
		</geometry>
  <material name="gray">
    <color rgba="0.8 0.8 0.8 1.0"/>
  </material>
		</visual>
		<collision>
		<origin rpy="0 0 0" xyz="0 0 0"/>
		<geometry>
		<mesh filename="meshes/link1.stl"/>
		</geometry>
		</collision>
		<inertial>
		<origin rpy="0 0 0" xyz="0 0 0"/>
		<mass value="0.705"/>
		  <inertia  ixx="0.0006111993117592239" ixy="0" ixz="0" iyy="0.000993951145190498" iyz="0" izz="0.0006111993117592239" />
		</inertial>
	</link>
<link name="link2">
		<visual>
		<origin rpy="0 0 0" xyz="0 0 0"/>
		<geometry>
		<mesh filename="meshes/link1.stl"/>
		</geometry>
  <material name="gray">
    <color rgba="0.8 0.8 0.8 1.0"/>
  </material>
		</visual>
		<collision>
		<origin rpy="0 0 0" xyz="0 0 0"/>
		<geometry>
		<mesh filename="meshes/link1.stl"/>
		</geometry>
		</collision>
		<inertial>
		<origin rpy="0 0 0" xyz="0 0 0"/>
		<mass value="0.705"/>
		  <inertia  ixx="0.0006111993117592239" ixy="0" ixz="0" iyy="0.000993951145190498" iyz="0" izz="0.0006111993117592239" />
		</inertial>
	</link>
	<joint name="joint2" type="revolute">
		<parent link="base_link"/>
		<child link="link2"/>
		<origin rpy="0.0 0.0 3.141592" xyz="-0.20956 -0.1476 -0.075093"/>
		<axis xyz="1 0 0"/>
               <limit effort="10" lower="-3.05432619099" upper="3.05432619099" velocity="1"/>
	</joint>	
</robot>